<robot name="onshape">
<link name="l0">
<visual>
<origin xyz="0 -1.7140217468436077262e-18 0" rpy="0 -0 -1.570796326794896558" />
<geometry>
<mesh filename="package:///l0.stl"/>
</geometry>
<material name="l0_material">
<color rgba="0.90196078431372550543 0.90196078431372550543 0.90196078431372550543 1.0"/>
</material>
</visual>
<collision>
<origin xyz="0 -1.7140217468436077262e-18 0" rpy="0 -0 -1.570796326794896558" />
<geometry>
<mesh filename="package:///l0.stl"/>
</geometry>
</collision>
<inertial>
<origin xyz="0 -1.5131598233853726474e-18 0.049999999999999995837" rpy="0 0 0"/>
<mass value="24.827535209761190771" />
<inertia ixx="0.085134134852137541283" ixy="0"  ixz="0" iyy="0.085134134852137541283" iyz="0" izz="0.12888904435467307685" />
</inertial>
</link>

<link name="l1">
<visual>
<origin xyz="0 4.5924254968025743728e-18 0.10000000000000000555" rpy="-3.141592653589793116 1.7077893049809921871e-32 -8.063326666779573049e-19" />
<geometry>
<mesh filename="package:///l1.stl"/>
</geometry>
<material name="l1_material">
<color rgba="0.4000000000000000222 0.4000000000000000222 0.4000000000000000222 1.0"/>
</material>
</visual>
<collision>
<origin xyz="0 4.5924254968025743728e-18 0.10000000000000000555" rpy="-3.141592653589793116 1.7077893049809921871e-32 -8.063326666779573049e-19" />
<geometry>
<mesh filename="package:///l1.stl"/>
</geometry>
</collision>
<inertial>
<origin xyz="-1.3813667566118144498e-18 2.9846895923880740379e-18 -0.042125157722663647553" rpy="0 0 0"/>
<mass value="9.6269996423763473103" />
<inertia ixx="0.020993221031819456202" ixy="-3.4627005843019532163e-20"  ixz="-4.080146558311789525e-34" iyy="0.020523165820632190137" iyz="1.520906964852000759e-34" izz="0.021592260157852545543" />
</inertial>
</link>

<link name="l2">
<visual>
<origin xyz="0.26999999999999990674 1.9081958235744878039e-17 0.030000000000000037054" rpy="-1.570796326794896558 -1.570796326794896336 0" />
<geometry>
<mesh filename="package:///l2.stl"/>
</geometry>
<material name="l2_material">
<color rgba="0.4000000000000000222 0.4000000000000000222 0.4000000000000000222 1.0"/>
</material>
</visual>
<collision>
<origin xyz="0.26999999999999990674 1.9081958235744878039e-17 0.030000000000000037054" rpy="-1.570796326794896558 -1.570796326794896336 0" />
<geometry>
<mesh filename="package:///l2.stl"/>
</geometry>
</collision>
<inertial>
<origin xyz="0.26999999999999990674 2.0939880835670430227e-17 0.030000000000000019706" rpy="0 0 0"/>
<mass value="12.030090139840790897" />
<inertia ixx="0.021840832533890710415" ixy="9.697551312447906581e-19"  ixz="-5.5741012850395494526e-17" iyy="0.33671105164493336792" iyz="1.4272418454029100561e-19" izz="0.321836725871174123" />
</inertial>
</link>

<link name="l3">
<visual>
<origin xyz="-0.27000000000000023981 5.5511151231257827021e-17 -0.030000000000000019706" rpy="1.570796326794896558 1.570796326794896336 0" />
<geometry>
<mesh filename="package:///l3.stl"/>
</geometry>
<material name="l3_material">
<color rgba="0.4000000000000000222 0.4000000000000000222 0.4000000000000000222 1.0"/>
</material>
</visual>
<collision>
<origin xyz="-0.27000000000000023981 5.5511151231257827021e-17 -0.030000000000000019706" rpy="1.570796326794896558 1.570796326794896336 0" />
<geometry>
<mesh filename="package:///l3.stl"/>
</geometry>
</collision>
<inertial>
<origin xyz="0.15905826152025803744 3.6854707919516950693e-17 -0.030000000000000002359" rpy="0 0 0"/>
<mass value="10.022083122178289116" />
<inertia ixx="0.0055885165329786056637" ixy="9.207473570448607957e-19"  ixz="1.9890845184674162257e-17" iyy="0.11512374341180875437" iyz="-4.6463354415219668926e-19" izz="0.11508496611053907477" />
</inertial>
</link>

<link name="l4">
<visual>
<origin xyz="5.2041704279304212832e-18 -1.6653345369377348106e-16 0.61999999999999999556" rpy="-1.570796326794896558 -1.8147407581527472873e-16 -9.8103749977977800754e-19" />
<geometry>
<mesh filename="package:///l4.stl"/>
</geometry>
<material name="l4_material">
<color rgba="0.4000000000000000222 0.4000000000000000222 0.4000000000000000222 1.0"/>
</material>
</visual>
<collision>
<origin xyz="5.2041704279304212832e-18 -1.6653345369377348106e-16 0.61999999999999999556" rpy="-1.570796326794896558 -1.8147407581527472873e-16 -9.8103749977977800754e-19" />
<geometry>
<mesh filename="package:///l4.stl"/>
</geometry>
</collision>
<inertial>
<origin xyz="-6.0776637997405902332e-17 -9.1534840093330376864e-17 -0.03666272435396966678" rpy="0 0 0"/>
<mass value="2.7315915489442814668" />
<inertia ixx="0.002738555176116049851" ixy="-9.2403123313618038721e-21"  ixz="-2.4412126175778179178e-19" iyy="0.0050819937319632468853" iyz="-3.5963225907744954126e-19" izz="0.003915807428920928604" />
</inertial>
</link>

<link name="l5">
<visual>
<origin xyz="-0.69000000000000016875 8.3266726846886740532e-17 -0.029999999999999787254" rpy="1.570796326794896558 1.570796326794896336 0" />
<geometry>
<mesh filename="package:///l5.stl"/>
</geometry>
<material name="l5_material">
<color rgba="0.92156862745098033773 0.80000000000000004441 0.65490196078431373028 1.0"/>
</material>
</visual>
<collision>
<origin xyz="-0.69000000000000016875 8.3266726846886740532e-17 -0.029999999999999787254" rpy="1.570796326794896558 1.570796326794896336 0" />
<geometry>
<mesh filename="package:///l5.stl"/>
</geometry>
</collision>
<inertial>
<origin xyz="0.030985121906162538252 1.0411727091115720004e-16 -0.029999999999999929501" rpy="0 0 0"/>
<mass value="2.9575000242897417913" />
<inertia ixx="0.0015698237165542331881" ixy="2.2401781196467238758e-22"  ixz="7.5917419284102489712e-19" iyy="0.0038848162281158540345" iyz="-1.3360625174782692738e-20" izz="0.0038460389268461683647" />
</inertial>
</link>

<link name="l6">
<visual>
<origin xyz="2.498001805406602216e-16 2.7755575615628913511e-17 0.78000000000000024869" rpy="-1.570796326794896558 -4.6294970802633059035e-18 -1.3591692068730298233e-18" />
<geometry>
<mesh filename="package:///l6.stl"/>
</geometry>
<material name="l6_material">
<color rgba="0.86666666666666669627 0.32156862745098041545 0.15686274509803921351 1.0"/>
</material>
</visual>
<collision>
<origin xyz="2.498001805406602216e-16 2.7755575615628913511e-17 0.78000000000000024869" rpy="-1.570796326794896558 -4.6294970802633059035e-18 -1.3591692068730298233e-18" />
<geometry>
<mesh filename="package:///l6.stl"/>
</geometry>
</collision>
<inertial>
<origin xyz="5.8496633797018876264e-10 2.6864690780004197737e-17 -0.084638548872363550402" rpy="0 0 0"/>
<mass value="4.4738599624546244726" />
<inertia ixx="0.0084132518345757280331" ixy="1.1175930029912302542e-09"  ixz="-3.3925322753960209592e-10" iyy="0.016236159614768125303" iyz="-1.2598187259148252329e-20" izz="0.0082887869045292425496" />
</inertial>
</link>

<joint name="j5" type="revolute">
<origin xyz="0.090000000000000190958 8.3266726846886740532e-17 -0.029999999999999783784" rpy="-1.570796326794896558 -1.5460417158233572543 1.5707963267950684205" />
<parent link="l5" />
<child link="l6" />
<axis xyz="0 0 1"/>
<limit effort="1" velocity="20" />
<joint_properties friction="0.0"/>
</joint>

<joint name="j4" type="revolute">
<origin xyz="-0.02999999999999987399 -5.5511151231257827021e-17 -0.070000000000000117684" rpy="1.57079632679489678 1.0576205535712408512 -1.5707963267949329733" />
<parent link="l4" />
<child link="l5" />
<axis xyz="0 0 1"/>
<limit effort="1" velocity="20" lower="-1.570796326794896558" upper="1.570796326794896558"/>
<joint_properties friction="0.0"/>
</joint>

<joint name="j3" type="revolute">
<origin xyz="0.35000000000000003331 0 -0.030000000000000016237" rpy="-1.570796326794896336 -1.5377805592522608702 1.5707963267947766539" />
<parent link="l3" />
<child link="l4" />
<axis xyz="0 0 1"/>
<limit effort="1" velocity="20" />
<joint_properties friction="0.0"/>
</joint>

<joint name="j2" type="revolute">
<origin xyz="0.53999999999999970246 4.2500725161431773813e-17 -5.2041704279304212832e-17" rpy="3.1415926535897922278 -3.5358369347484718404e-16 2.6533810162595874438" />
<parent link="l2" />
<child link="l3" />
<axis xyz="0 0 1"/>
<limit effort="1" velocity="20" lower="-2.9670597283903603625" upper="2.9670597283903603625"/>
<joint_properties friction="0.0"/>
</joint>

<joint name="j1" type="revolute">
<origin xyz="-0.030000000000000002359 -5.939064054361224748e-18 -0.090000000000000024425" rpy="-1.5707963267948927832 1.5355088814176045542 -1.5707963267948952257" />
<parent link="l1" />
<child link="l2" />
<axis xyz="0 0 1"/>
<limit effort="1" velocity="20" lower="0" upper="3.141592653589793116"/>
<joint_properties friction="0.0"/>
</joint>

<joint name="j0" type="revolute">
<origin xyz="-2.4737668906151284466e-20 3.7960383935658583618e-20 0.10000000000000003331" rpy="3.141592653589793116 1.4513261214963706939e-16 1.5294582191363306212" />
<parent link="l0" />
<child link="l1" />
<axis xyz="0 0 1"/>
<limit effort="1" velocity="20" />
<joint_properties friction="0.0"/>
</joint>


</robot>
